# api_connectors/core/exceptions.py
class APIError(Exception):
    """Erreur lors de l'appel d'une API externe"""
    pass
